Workbook

Sheet Progress Summary
B2: One Playlist to Make You a Data Engineer
B3: Progress Tracker
B4: CLICK HERE TO OPEN THE PLAYLIST ON YOUTUBE
B6: =IFERROR((SUMIF('Course Videos'!$G$2:$G$79,"Completed",'Course Videos'!$F$2:$F$79)+0.5*SUMIF('Course Videos'!$G$2:$G$79,"In Progress",'Course Videos'!$F$2:$F$79))/SUM('Course Videos'!$F$2:$F$79),0) | D6: Videos done | E6: =COUNTIF('Course Videos'!$G$2:$G$79,"Completed")&" / "&COUNTA('Course Videos'!$G$2:$G$79)
D7: Hours watched | E7: =IFERROR(SUMIF('Course Videos'!$G$2:$G$79,"Completed",'Course Videos'!$F$2:$F$79)/60,0)
D8: Hours remaining | E8: =IFERROR((SUM('Course Videos'!$F$2:$F$79)-SUMIF('Course Videos'!$G$2:$G$79,"Completed",'Course Videos'!$F$2:$F$79))/60,0)
B9: OVERALL PROGRESS (weighted by watch time) | D9: Progress by count | E9: =IFERROR((COUNTIF('Course Videos'!$G$2:$G$79,"Completed")+0.5*COUNTIF('Course Videos'!$G$2:$G$79,"In Progress"))/COUNTA('Course Videos'!$G$2:$G$79),0)
B10: ="Total course length: "&TEXT(SUM('Course Videos'!$F$2:$F$79)/60,"0.0")&" hours across "&COUNTA('Course Videos'!$G$2:$G$79)&" videos"
B12: SECTION | C12: Videos | D12: Done | E12: Hours | F12: Progress
B13: 0. Start Here | C13: =COUNTIF('Course Videos'!$B$2:$B$79,"0. Start Here") | D13: =COUNTIFS('Course Videos'!$B$2:$B$79,"0. Start Here",'Course Videos'!$G$2:$G$79,"Completed") | E13: =IFERROR(SUMIF('Course Videos'!$B$2:$B$79,"0. Start Here",'Course Videos'!$F$2:$F$79)/60,0) | F13: =IFERROR(IF(SUMIF('Course Videos'!$B$2:$B$79,"0. Start Here",'Course Videos'!$F$2:$F$79)=0,(COUNTIFS('Course Videos'!$B$2:$B$79,"0. Start Here",'Course Videos'!$G$2:$G$79,"Completed")+0.5*COUNTIFS('Course Videos'!$B$2:$B$79,"0. Start Here",'Course Videos'!$G$2:$G$79,"In Progress"))/COUNTIF('Course Videos'!$B$2:$B$79,"0. Start Here"),(SUMIFS('Course Videos'!$F$2:$F$79,'Course Videos'!$B$2:$B$79,"0. Start Here",'Course Videos'!$G$2:$G$79,"Completed")+0.5*SUMIFS('Course Videos'!$F$2:$F$79,'Course Videos'!$B$2:$B$79,"0. Start Here",'Course Videos'!$G$2:$G$79,"In Progress"))/SUMIF('Course Videos'!$B$2:$B$79,"0. Start Here",'Course Videos'!$F$2:$F$79)),0)
B14: 1. Spark Foundations | C14: =COUNTIF('Course Videos'!$B$2:$B$79,"1. Spark Foundations") | D14: =COUNTIFS('Course Videos'!$B$2:$B$79,"1. Spark Foundations",'Course Videos'!$G$2:$G$79,"Completed") | E14: =IFERROR(SUMIF('Course Videos'!$B$2:$B$79,"1. Spark Foundations",'Course Videos'!$F$2:$F$79)/60,0) | F14: =IFERROR(IF(SUMIF('Course Videos'!$B$2:$B$79,"1. Spark Foundations",'Course Videos'!$F$2:$F$79)=0,(COUNTIFS('Course Videos'!$B$2:$B$79,"1. Spark Foundations",'Course Videos'!$G$2:$G$79,"Completed")+0.5*COUNTIFS('Course Videos'!$B$2:$B$79,"1. Spark Foundations",'Course Videos'!$G$2:$G$79,"In Progress"))/COUNTIF('Course Videos'!$B$2:$B$79,"1. Spark Foundations"),(SUMIFS('Course Videos'!$F$2:$F$79,'Course Videos'!$B$2:$B$79,"1. Spark Foundations",'Course Videos'!$G$2:$G$79,"Completed")+0.5*SUMIFS('Course Videos'!$F$2:$F$79,'Course Videos'!$B$2:$B$79,"1. Spark Foundations",'Course Videos'!$G$2:$G$79,"In Progress"))/SUMIF('Course Videos'!$B$2:$B$79,"1. Spark Foundations",'Course Videos'!$F$2:$F$79)),0)
B15: 2. Reading Data with PySpark | C15: =COUNTIF('Course Videos'!$B$2:$B$79,"2. Reading Data with PySpark") | D15: =COUNTIFS('Course Videos'!$B$2:$B$79,"2. Reading Data with PySpark",'Course Videos'!$G$2:$G$79,"Completed") | E15: =IFERROR(SUMIF('Course Videos'!$B$2:$B$79,"2. Reading Data with PySpark",'Course Videos'!$F$2:$F$79)/60,0) | F15: =IFERROR(IF(SUMIF('Course Videos'!$B$2:$B$79,"2. Reading Data with PySpark",'Course Videos'!$F$2:$F$79)=0,(COUNTIFS('Course Videos'!$B$2:$B$79,"2. Reading Data with PySpark",'Course Videos'!$G$2:$G$79,"Completed")+0.5*COUNTIFS('Course Videos'!$B$2:$B$79,"2. Reading Data with PySpark",'Course Videos'!$G$2:$G$79,"In Progress"))/COUNTIF('Course Videos'!$B$2:$B$79,"2. Reading Data with PySpark"),(SUMIFS('Course Videos'!$F$2:$F$79,'Course Videos'!$B$2:$B$79,"2. Reading Data with PySpark",'Course Videos'!$G$2:$G$79,"Completed")+0.5*SUMIFS('Course Videos'!$F$2:$F$79,'Course Videos'!$B$2:$B$79,"2. Reading Data with PySpark",'Course Videos'!$G$2:$G$79,"In Progress"))/SUMIF('Course Videos'!$B$2:$B$79,"2. Reading Data with PySpark",'Course Videos'!$F$2:$F$79)),0)
B16: 3. Transformations & Performance (PySpark + SQL) | C16: =COUNTIF('Course Videos'!$B$2:$B$79,"3. Transformations & Performance (PySpark + SQL)") | D16: =COUNTIFS('Course Videos'!$B$2:$B$79,"3. Transformations & Performance (PySpark + SQL)",'Course Videos'!$G$2:$G$79,"Completed") | E16: =IFERROR(SUMIF('Course Videos'!$B$2:$B$79,"3. Transformations & Performance (PySpark + SQL)",'Course Videos'!$F$2:$F$79)/60,0) | F16: =IFERROR(IF(SUMIF('Course Videos'!$B$2:$B$79,"3. Transformations & Performance (PySpark + SQL)",'Course Videos'!$F$2:$F$79)=0,(COUNTIFS('Course Videos'!$B$2:$B$79,"3. Transformations & Performance (PySpark + SQL)",'Course Videos'!$G$2:$G$79,"Completed")+0.5*COUNTIFS('Course Videos'!$B$2:$B$79,"3. Transformations & Performance (PySpark + SQL)",'Course Videos'!$G$2:$G$79,"In Progress"))/COUNTIF('Course Videos'!$B$2:$B$79,"3. Transformations & Performance (PySpark + SQL)"),(SUMIFS('Course Videos'!$F$2:$F$79,'Course Videos'!$B$2:$B$79,"3. Transformations & Performance (PySpark + SQL)",'Course Videos'!$G$2:$G$79,"Completed")+0.5*SUMIFS('Course Videos'!$F$2:$F$79,'Course Videos'!$B$2:$B$79,"3. Transformations & Performance (PySpark + SQL)",'Course Videos'!$G$2:$G$79,"In Progress"))/SUMIF('Course Videos'!$B$2:$B$79,"3. Transformations & Performance (PySpark + SQL)",'Course Videos'!$F$2:$F$79)),0)
B17: 4. Delta Lake & Lakehouse | C17: =COUNTIF('Course Videos'!$B$2:$B$79,"4. Delta Lake & Lakehouse") | D17: =COUNTIFS('Course Videos'!$B$2:$B$79,"4. Delta Lake & Lakehouse",'Course Videos'!$G$2:$G$79,"Completed") | E17: =IFERROR(SUMIF('Course Videos'!$B$2:$B$79,"4. Delta Lake & Lakehouse",'Course Videos'!$F$2:$F$79)/60,0) | F17: =IFERROR(IF(SUMIF('Course Videos'!$B$2:$B$79,"4. Delta Lake & Lakehouse",'Course Videos'!$F$2:$F$79)=0,(COUNTIFS('Course Videos'!$B$2:$B$79,"4. Delta Lake & Lakehouse",'Course Videos'!$G$2:$G$79,"Completed")+0.5*COUNTIFS('Course Videos'!$B$2:$B$79,"4. Delta Lake & Lakehouse",'Course Videos'!$G$2:$G$79,"In Progress"))/COUNTIF('Course Videos'!$B$2:$B$79,"4. Delta Lake & Lakehouse"),(SUMIFS('Course Videos'!$F$2:$F$79,'Course Videos'!$B$2:$B$79,"4. Delta Lake & Lakehouse",'Course Videos'!$G$2:$G$79,"Completed")+0.5*SUMIFS('Course Videos'!$F$2:$F$79,'Course Videos'!$B$2:$B$79,"4. Delta Lake & Lakehouse",'Course Videos'!$G$2:$G$79,"In Progress"))/SUMIF('Course Videos'!$B$2:$B$79,"4. Delta Lake & Lakehouse",'Course Videos'!$F$2:$F$79)),0)
B18: 5. Milestone: Finance Domain End-to-End Project | C18: =COUNTIF('Course Videos'!$B$2:$B$79,"5. Milestone: Finance Domain End-to-End Project") | D18: =COUNTIFS('Course Videos'!$B$2:$B$79,"5. Milestone: Finance Domain End-to-End Project",'Course Videos'!$G$2:$G$79,"Completed") | E18: =IFERROR(SUMIF('Course Videos'!$B$2:$B$79,"5. Milestone: Finance Domain End-to-End Project",'Course Videos'!$F$2:$F$79)/60,0) | F18: =IFERROR(IF(SUMIF('Course Videos'!$B$2:$B$79,"5. Milestone: Finance Domain End-to-End Project",'Course Videos'!$F$2:$F$79)=0,(COUNTIFS('Course Videos'!$B$2:$B$79,"5. Milestone: Finance Domain End-to-End Project",'Course Videos'!$G$2:$G$79,"Completed")+0.5*COUNTIFS('Course Videos'!$B$2:$B$79,"5. Milestone: Finance Domain End-to-End Project",'Course Videos'!$G$2:$G$79,"In Progress"))/COUNTIF('Course Videos'!$B$2:$B$79,"5. Milestone: Finance Domain End-to-End Project"),(SUMIFS('Course Videos'!$F$2:$F$79,'Course Videos'!$B$2:$B$79,"5. Milestone: Finance Domain End-to-End Project",'Course Videos'!$G$2:$G$79,"Completed")+0.5*SUMIFS('Course Videos'!$F$2:$F$79,'Course Videos'!$B$2:$B$79,"5. Milestone: Finance Domain End-to-End Project",'Course Videos'!$G$2:$G$79,"In Progress"))/SUMIF('Course Videos'!$B$2:$B$79,"5. Milestone: Finance Domain End-to-End Project",'Course Videos'!$F$2:$F$79)),0)
B19: 6. Python for Data Engineering | C19: =COUNTIF('Course Videos'!$B$2:$B$79,"6. Python for Data Engineering") | D19: =COUNTIFS('Course Videos'!$B$2:$B$79,"6. Python for Data Engineering",'Course Videos'!$G$2:$G$79,"Completed") | E19: =IFERROR(SUMIF('Course Videos'!$B$2:$B$79,"6. Python for Data Engineering",'Course Videos'!$F$2:$F$79)/60,0) | F19: =IFERROR(IF(SUMIF('Course Videos'!$B$2:$B$79,"6. Python for Data Engineering",'Course Videos'!$F$2:$F$79)=0,(COUNTIFS('Course Videos'!$B$2:$B$79,"6. Python for Data Engineering",'Course Videos'!$G$2:$G$79,"Completed")+0.5*COUNTIFS('Course Videos'!$B$2:$B$79,"6. Python for Data Engineering",'Course Videos'!$G$2:$G$79,"In Progress"))/COUNTIF('Course Videos'!$B$2:$B$79,"6. Python for Data Engineering"),(SUMIFS('Course Videos'!$F$2:$F$79,'Course Videos'!$B$2:$B$79,"6. Python for Data Engineering",'Course Videos'!$G$2:$G$79,"Completed")+0.5*SUMIFS('Course Videos'!$F$2:$F$79,'Course Videos'!$B$2:$B$79,"6. Python for Data Engineering",'Course Videos'!$G$2:$G$79,"In Progress"))/SUMIF('Course Videos'!$B$2:$B$79,"6. Python for Data Engineering",'Course Videos'!$F$2:$F$79)),0)
B20: 7. Databricks Platform Essentials | C20: =COUNTIF('Course Videos'!$B$2:$B$79,"7. Databricks Platform Essentials") | D20: =COUNTIFS('Course Videos'!$B$2:$B$79,"7. Databricks Platform Essentials",'Course Videos'!$G$2:$G$79,"Completed") | E20: =IFERROR(SUMIF('Course Videos'!$B$2:$B$79,"7. Databricks Platform Essentials",'Course Videos'!$F$2:$F$79)/60,0) | F20: =IFERROR(IF(SUMIF('Course Videos'!$B$2:$B$79,"7. Databricks Platform Essentials",'Course Videos'!$F$2:$F$79)=0,(COUNTIFS('Course Videos'!$B$2:$B$79,"7. Databricks Platform Essentials",'Course Videos'!$G$2:$G$79,"Completed")+0.5*COUNTIFS('Course Videos'!$B$2:$B$79,"7. Databricks Platform Essentials",'Course Videos'!$G$2:$G$79,"In Progress"))/COUNTIF('Course Videos'!$B$2:$B$79,"7. Databricks Platform Essentials"),(SUMIFS('Course Videos'!$F$2:$F$79,'Course Videos'!$B$2:$B$79,"7. Databricks Platform Essentials",'Course Videos'!$G$2:$G$79,"Completed")+0.5*SUMIFS('Course Videos'!$F$2:$F$79,'Course Videos'!$B$2:$B$79,"7. Databricks Platform Essentials",'Course Videos'!$G$2:$G$79,"In Progress"))/SUMIF('Course Videos'!$B$2:$B$79,"7. Databricks Platform Essentials",'Course Videos'!$F$2:$F$79)),0)
B21: 8. Databricks Advanced & Production | C21: =COUNTIF('Course Videos'!$B$2:$B$79,"8. Databricks Advanced & Production") | D21: =COUNTIFS('Course Videos'!$B$2:$B$79,"8. Databricks Advanced & Production",'Course Videos'!$G$2:$G$79,"Completed") | E21: =IFERROR(SUMIF('Course Videos'!$B$2:$B$79,"8. Databricks Advanced & Production",'Course Videos'!$F$2:$F$79)/60,0) | F21: =IFERROR(IF(SUMIF('Course Videos'!$B$2:$B$79,"8. Databricks Advanced & Production",'Course Videos'!$F$2:$F$79)=0,(COUNTIFS('Course Videos'!$B$2:$B$79,"8. Databricks Advanced & Production",'Course Videos'!$G$2:$G$79,"Completed")+0.5*COUNTIFS('Course Videos'!$B$2:$B$79,"8. Databricks Advanced & Production",'Course Videos'!$G$2:$G$79,"In Progress"))/COUNTIF('Course Videos'!$B$2:$B$79,"8. Databricks Advanced & Production"),(SUMIFS('Course Videos'!$F$2:$F$79,'Course Videos'!$B$2:$B$79,"8. Databricks Advanced & Production",'Course Videos'!$G$2:$G$79,"Completed")+0.5*SUMIFS('Course Videos'!$F$2:$F$79,'Course Videos'!$B$2:$B$79,"8. Databricks Advanced & Production",'Course Videos'!$G$2:$G$79,"In Progress"))/SUMIF('Course Videos'!$B$2:$B$79,"8. Databricks Advanced & Production",'Course Videos'!$F$2:$F$79)),0)
B22: 9. Milestone: Retail Project (Databricks) | C22: =COUNTIF('Course Videos'!$B$2:$B$79,"9. Milestone: Retail Project (Databricks)") | D22: =COUNTIFS('Course Videos'!$B$2:$B$79,"9. Milestone: Retail Project (Databricks)",'Course Videos'!$G$2:$G$79,"Completed") | E22: =IFERROR(SUMIF('Course Videos'!$B$2:$B$79,"9. Milestone: Retail Project (Databricks)",'Course Videos'!$F$2:$F$79)/60,0) | F22: =IFERROR(IF(SUMIF('Course Videos'!$B$2:$B$79,"9. Milestone: Retail Project (Databricks)",'Course Videos'!$F$2:$F$79)=0,(COUNTIFS('Course Videos'!$B$2:$B$79,"9. Milestone: Retail Project (Databricks)",'Course Videos'!$G$2:$G$79,"Completed")+0.5*COUNTIFS('Course Videos'!$B$2:$B$79,"9. Milestone: Retail Project (Databricks)",'Course Videos'!$G$2:$G$79,"In Progress"))/COUNTIF('Course Videos'!$B$2:$B$79,"9. Milestone: Retail Project (Databricks)"),(SUMIFS('Course Videos'!$F$2:$F$79,'Course Videos'!$B$2:$B$79,"9. Milestone: Retail Project (Databricks)",'Course Videos'!$G$2:$G$79,"Completed")+0.5*SUMIFS('Course Videos'!$F$2:$F$79,'Course Videos'!$B$2:$B$79,"9. Milestone: Retail Project (Databricks)",'Course Videos'!$G$2:$G$79,"In Progress"))/SUMIF('Course Videos'!$B$2:$B$79,"9. Milestone: Retail Project (Databricks)",'Course Videos'!$F$2:$F$79)),0)
B23: 10. Data Modeling & Azure Data Factory | C23: =COUNTIF('Course Videos'!$B$2:$B$79,"10. Data Modeling & Azure Data Factory") | D23: =COUNTIFS('Course Videos'!$B$2:$B$79,"10. Data Modeling & Azure Data Factory",'Course Videos'!$G$2:$G$79,"Completed") | E23: =IFERROR(SUMIF('Course Videos'!$B$2:$B$79,"10. Data Modeling & Azure Data Factory",'Course Videos'!$F$2:$F$79)/60,0) | F23: =IFERROR(IF(SUMIF('Course Videos'!$B$2:$B$79,"10. Data Modeling & Azure Data Factory",'Course Videos'!$F$2:$F$79)=0,(COUNTIFS('Course Videos'!$B$2:$B$79,"10. Data Modeling & Azure Data Factory",'Course Videos'!$G$2:$G$79,"Completed")+0.5*COUNTIFS('Course Videos'!$B$2:$B$79,"10. Data Modeling & Azure Data Factory",'Course Videos'!$G$2:$G$79,"In Progress"))/COUNTIF('Course Videos'!$B$2:$B$79,"10. Data Modeling & Azure Data Factory"),(SUMIFS('Course Videos'!$F$2:$F$79,'Course Videos'!$B$2:$B$79,"10. Data Modeling & Azure Data Factory",'Course Videos'!$G$2:$G$79,"Completed")+0.5*SUMIFS('Course Videos'!$F$2:$F$79,'Course Videos'!$B$2:$B$79,"10. Data Modeling & Azure Data Factory",'Course Videos'!$G$2:$G$79,"In Progress"))/SUMIF('Course Videos'!$B$2:$B$79,"10. Data Modeling & Azure Data Factory",'Course Videos'!$F$2:$F$79)),0)
B24: 11. Milestone: End-to-End Azure Project | C24: =COUNTIF('Course Videos'!$B$2:$B$79,"11. Milestone: End-to-End Azure Project") | D24: =COUNTIFS('Course Videos'!$B$2:$B$79,"11. Milestone: End-to-End Azure Project",'Course Videos'!$G$2:$G$79,"Completed") | E24: =IFERROR(SUMIF('Course Videos'!$B$2:$B$79,"11. Milestone: End-to-End Azure Project",'Course Videos'!$F$2:$F$79)/60,0) | F24: =IFERROR(IF(SUMIF('Course Videos'!$B$2:$B$79,"11. Milestone: End-to-End Azure Project",'Course Videos'!$F$2:$F$79)=0,(COUNTIFS('Course Videos'!$B$2:$B$79,"11. Milestone: End-to-End Azure Project",'Course Videos'!$G$2:$G$79,"Completed")+0.5*COUNTIFS('Course Videos'!$B$2:$B$79,"11. Milestone: End-to-End Azure Project",'Course Videos'!$G$2:$G$79,"In Progress"))/COUNTIF('Course Videos'!$B$2:$B$79,"11. Milestone: End-to-End Azure Project"),(SUMIFS('Course Videos'!$F$2:$F$79,'Course Videos'!$B$2:$B$79,"11. Milestone: End-to-End Azure Project",'Course Videos'!$G$2:$G$79,"Completed")+0.5*SUMIFS('Course Videos'!$F$2:$F$79,'Course Videos'!$B$2:$B$79,"11. Milestone: End-to-End Azure Project",'Course Videos'!$G$2:$G$79,"In Progress"))/SUMIF('Course Videos'!$B$2:$B$79,"11. Milestone: End-to-End Azure Project",'Course Videos'!$F$2:$F$79)),0)
B25: 12. Interview Prep & Career | C25: =COUNTIF('Course Videos'!$B$2:$B$79,"12. Interview Prep & Career") | D25: =COUNTIFS('Course Videos'!$B$2:$B$79,"12. Interview Prep & Career",'Course Videos'!$G$2:$G$79,"Completed") | E25: =IFERROR(SUMIF('Course Videos'!$B$2:$B$79,"12. Interview Prep & Career",'Course Videos'!$F$2:$F$79)/60,0) | F25: =IFERROR(IF(SUMIF('Course Videos'!$B$2:$B$79,"12. Interview Prep & Career",'Course Videos'!$F$2:$F$79)=0,(COUNTIFS('Course Videos'!$B$2:$B$79,"12. Interview Prep & Career",'Course Videos'!$G$2:$G$79,"Completed")+0.5*COUNTIFS('Course Videos'!$B$2:$B$79,"12. Interview Prep & Career",'Course Videos'!$G$2:$G$79,"In Progress"))/COUNTIF('Course Videos'!$B$2:$B$79,"12. Interview Prep & Career"),(SUMIFS('Course Videos'!$F$2:$F$79,'Course Videos'!$B$2:$B$79,"12. Interview Prep & Career",'Course Videos'!$G$2:$G$79,"Completed")+0.5*SUMIFS('Course Videos'!$F$2:$F$79,'Course Videos'!$B$2:$B$79,"12. Interview Prep & Career",'Course Videos'!$G$2:$G$79,"In Progress"))/SUMIF('Course Videos'!$B$2:$B$79,"12. Interview Prep & Career",'Course Videos'!$F$2:$F$79)),0)
B27: HOW TO USE
B28: • Open the 'Course Videos' tab and set Completion Status from the dropdown. Everything on this page updates itself.
B29: • Progress is weighted by video length, so finishing a 6-hour course moves the bar far more than a 3-minute explainer.
B30: • A video marked In Progress counts as half complete.
B31: • Only Completion Status, Date Completed and Notes are editable. The rest is locked so a stray edit cannot break the formulas (Review > Unprotect Sheet if you want to change something).
B32: • Row 1 is the course intro video, added once it is published.

Sheet Course Videos
A1: Sr No | B1: Section | C1: Video Title | D1: Video URL | E1: Updated Date | F1: Duration (min) | G1: Completion Status | H1: Date Completed | I1: Notes
A2: 0. START HERE
A3: 1 | B3: 0. Start Here | C3: Course Introduction - How to Use This Roadmap | D3: (link to be added) | E3: 46294 | G3: Not Started
A4: 1. SPARK FOUNDATIONS
A5: 2 | B5: 1. Spark Foundations | C5: 02 | History of Spark, Databricks, Big Data & Hadoop | D5: Watch on YouTube | E5: 46294 | F5: 6.5 | G5: Not Started
A6: 3 | B6: 1. Spark Foundations | C6: 03 | What is Apache Spark? | D6: Watch on YouTube | E6: 46294 | F6: 3.1 | G6: Not Started
A7: 4 | B7: 1. Spark Foundations | C7: 04 | Apache Spark Architecture Explained | D7: Watch on YouTube | E7: 46294 | F7: 8.8 | G7: Not Started
A8: 5 | B8: 1. Spark Foundations | C8: 05 | Spark Deployment Modes Explained | Local, Client & Cluster | D8: Watch on YouTube | E8: 46294 | F8: 3.3 | G8: Not Started
A9: 6 | B9: 1. Spark Foundations | C9: 06 | Databricks Free Account Setup & Hands-On Tutorial | D9: Watch on YouTube | E9: 46294 | F9: 11.4 | G9: Not Started
A10: 7 | B10: 1. Spark Foundations | C10: 07 | Apache Spark APIs Explained | RDDs, DataFrames, Datasets, SQL & More | D10: Watch on YouTube | E10: 46294 | F10: 3.7 | G10: Not Started
A11: 2. READING DATA WITH PYSPARK
A12: 8 | B12: 2. Reading Data with PySpark | C12: 08 | Read CSV Files in Spark | Handle Delimiters, Quotes, Escapes & Multi-Line Records | D12: Watch on YouTube | E12: 46294 | F12: 17.4 | G12: Not Started
A13: 9 | B13: 2. Reading Data with PySpark | C13: 09 | Read JSON Files in Spark | Handle Single-Line and Multi-Line JSON in PySpark | D13: Watch on YouTube | E13: 46294 | F13: 6.8 | G13: Not Started
A14: 10 | B14: 2. Reading Data with PySpark | C14: Parquet Explained in Depth with PySpark | Internals, Columnar Format, Footers | D14: Watch on YouTube | E14: 46294 | F14: 13.1 | G14: Not Started
A15: 11 | B15: 2. Reading Data with PySpark | C15: Handle Corrupted Data in PySpark | Read Modes Explained | D15: Watch on YouTube | E15: 46294 | F15: 14.2 | G15: Not Started
A16: 12 | B16: 2. Reading Data with PySpark | C16: Read Unstructured Data in PySpark | Text and Binary Files in Spark | Databricks Tutorial | D16: Watch on YouTube | E16: 46294 | F16: 8.3 | G16: Not Started
A17: 13 | B17: 2. Reading Data with PySpark | C17: Connect to JDBC Data Sources in PySpark | Databricks SQL Warehouse Connection Tutorial | D17: Watch on YouTube | E17: 46294 | F17: 7.8 | G17: Not Started
A18: 3. TRANSFORMATIONS & PERFORMANCE (PYSPARK + SQL)
A19: 14 | B19: 3. Transformations & Performance (PySpark + SQL) | C19: PySpark - Narrow and Wide Transformation, Action, Lazy Evaluation & Shuffling | D19: Watch on YouTube | E19: 46294 | F19: 6.5 | G19: Not Started
A20: 15 | B20: 3. Transformations & Performance (PySpark + SQL) | C20: Common Transformations in PySpark & SQL | Select, Filter, Distinct, Union, Repartition vs Coalesce | D20: Watch on YouTube | E20: 46294 | F20: 34.6 | G20: Not Started
A21: 16 | B21: 3. Transformations & Performance (PySpark + SQL) | C21: Working with Numbers, Strings, Dates & Nulls in PySpark | D21: Watch on YouTube | E21: 46294 | F21: 21.6 | G21: Not Started
A22: 17 | B22: 3. Transformations & Performance (PySpark + SQL) | C22: Spark Execution Plan Explained | Logical Plan, Catalyst Optimizer & Physical Plan in PySpark | D22: Watch on YouTube | E22: 46294 | F22: 6.8 | G22: Not Started
A23: 18 | B23: 3. Transformations & Performance (PySpark + SQL) | C23: PySpark Aggregations Explained | Group By, Having, Collect Set, and Window Functions in Databricks | D23: Watch on YouTube | E23: 46294 | F23: 23 | G23: Not Started
A24: 19 | B24: 3. Transformations & Performance (PySpark + SQL) | C24: Work with Arrays, Structs & JSON Handling PySpark | D24: Watch on YouTube | E24: 46294 | F24: 13.6 | G24: Not Started
A25: 20 | B25: 3. Transformations & Performance (PySpark + SQL) | C25: PySpark Joins Explained | Inner, Outer, Left, Right, Semi & Cross Joins in Databricks | D25: Watch on YouTube | E25: 46294 | F25: 14.6 | G25: Not Started
A26: 21 | B26: 3. Transformations & Performance (PySpark + SQL) | C26: Broadcast Join vs Shuffle Hash Join Explained | PySpark Join Strategies in Databricks | D26: Watch on YouTube | E26: 46294 | F26: 13.7 | G26: Not Started
A27: 22 | B27: 3. Transformations & Performance (PySpark + SQL) | C27: Understanding Spark UI in Depth | Jobs, Stages, Tasks Explained in PySpark and Databricks | D27: Watch on YouTube | E27: 46294 | F27: 18.9 | G27: Not Started
A28: 23 | B28: 3. Transformations & Performance (PySpark + SQL) | C28: PySpark Cache vs Persist Explained | Storage Levels & Performance Optimization using Spark UI | D28: Watch on YouTube | E28: 46294 | F28: 14.9 | G28: Not Started
A29: 24 | B29: 3. Transformations & Performance (PySpark + SQL) | C29: PySpark Write Modes, File Formats & Partitioning Explained | D29: Watch on YouTube | E29: 46294 | F29: 14.2 | G29: Not Started
A30: 25 | B30: 3. Transformations & Performance (PySpark + SQL) | C30: Merge Operation Explained in PySpark | Insert, Update & Delete Data | D30: Watch on YouTube | E30: 46294 | F30: 11.6 | G30: Not Started
... A32: 27 | B32: 3. Transformations & Performance (PySpark + SQL) | C32: Spark Interview Questions & Answers | Crack Data Engineering Interviews Easily | D32: Watch on YouTube | E32: 46294 | F32: 58.9 | G32: Not Started
A33: 4. DELTA LAKE & LAKEHOUSE
A34: 28 | B34: 4. Delta Lake & Lakehouse | C34: Delta Lake Deepest Dive: Features and Hands-On Demo | D34: Watch on YouTube | E34: 46294 | F34: 29 | G34: Not Started
A35: 29 | B35: 4. Delta Lake & Lakehouse | C35: OPTIMIZE, ZORDER AND VACUUM in Delta Lake | Deep Dive with Demo | D35: Watch on YouTube | E35: 46294 | F35: 14.7 | G35: Not Started
A36: 30 | B36: 4. Delta Lake & Lakehouse | C36: Delta Table Cloning : Shallow vs Deep Clone with PySpark and Databricks | D36: Watch on YouTube | E36: 46294 | F36: 9.9 | G36: Not Started
A37: 31 | B37: 4. Delta Lake & Lakehouse | C37: Liquid Clustering vs Partitioning in Delta Lake | Deep Dive with Demo | D37: Watch on YouTube | E37: 46294 | F37: 13 | G37: Not Started
A38: 32 | B38: 4. Delta Lake & Lakehouse | C38: Delta Lake Change Data Feed: Enable, Query, and Real‑World Use Cases | D38: Watch on YouTube | E38: 46294 | F38: 10.7 | G38: Not Started
A39: 33 | B39: 4. Delta Lake & Lakehouse | C39: Delta Lake Interview Questions | D39: Watch on YouTube | E39: 46294 | F39: 22.6 | G39: Not Started
A40: 5. MILESTONE: FINANCE DOMAIN END-TO-END PROJECT
A41: 34 | B41: 5. Milestone: Finance Domain End-to-End Project | C41: Finance Domain End-to-End Data Engineering Project in Databricks (Free Edition) with Source Code | D41: Watch on YouTube | E41: 46294 | F41: 154.2 | G41: Not Started
...
